2025-10-07 07:52:25,749 - __main__ - INFO - üåü –ò–Ω–∏—Ü–∏–∞–ª–∏–∑–∞—Ü–∏—è —Å–∏—Å—Ç–µ–º—ã –±–∏–±–ª–∏–æ—Ç–µ–∫–∏...
2025-10-07 07:52:25,750 - __main__ - INFO - üöÄ –ó–∞–ø—É—Å–∫ Library Bot...
2025-10-07 07:52:27,095 - __main__ - ERROR - ‚ùå –û—à–∏–±–∫–∞ –ø—Ä–∏ –∑–∞–ø—É—Å–∫–µ Library Bot: Cannot close a running event loop
Traceback (most recent call last):
  File "/usr/local/lib/python3.11/site-packages/telegram/ext/_application.py", line 1054, in __run
    loop.run_until_complete(self._bootstrap_initialize(max_retries=bootstrap_retries))
  File "/usr/local/lib/python3.11/asyncio/base_events.py", line 630, in run_until_complete
    self._check_running()
  File "/usr/local/lib/python3.11/asyncio/base_events.py", line 589, in _check_running
    raise RuntimeError('This event loop is already running')
RuntimeError: This event loop is already running

During handling of the above exception, another exception occurred:

Traceback (most recent call last):
  File "/usr/local/lib/python3.11/site-packages/telegram/ext/_application.py", line 1079, in __run
    loop.run_until_complete(self.shutdown())
  File "/usr/local/lib/python3.11/asyncio/base_events.py", line 630, in run_until_complete
    self._check_running()
  File "/usr/local/lib/python3.11/asyncio/base_events.py", line 589, in _check_running
    raise RuntimeError('This event loop is already running')
RuntimeError: This event loop is already running

During handling of the above exception, another exception occurred:

Traceback (most recent call last):
  File "/app/src/main.py", line 31, in run_bot
    await module.main()
          ^^^^^^^^^^^^^
  File "/app/src/library_bot/main.py", line 142, in main
    application.run_polling()
  File "/usr/local/lib/python3.11/site-packages/telegram/ext/_application.py", line 839, in run_polling
    return self.__run(
           ^^^^^^^^^^^
  File "/usr/local/lib/python3.11/site-packages/telegram/ext/_application.py", line 1084, in __run
    loop.close()
  File "/usr/local/lib/python3.11/asyncio/unix_events.py", line 68, in close
    super().close()
  File "/usr/local/lib/python3.11/asyncio/selector_events.py", line 88, in close
    raise RuntimeError("Cannot close a running event loop")
RuntimeError: Cannot close a running event loop
2025-10-07 07:52:27,117 - __main__ - INFO - üöÄ –ó–∞–ø—É—Å–∫ Admin Bot...
2025-10-07 07:52:27,394 - __main__ - ERROR - ‚ùå –û—à–∏–±–∫–∞ –ø—Ä–∏ –∑–∞–ø—É—Å–∫–µ Admin Bot: Cannot close a running event loop
Traceback (most recent call last):
  File "/usr/local/lib/python3.11/site-packages/telegram/ext/_application.py", line 1054, in __run
    loop.run_until_complete(self._bootstrap_initialize(max_retries=bootstrap_retries))
  File "/usr/local/lib/python3.11/asyncio/base_events.py", line 630, in run_until_complete
    self._check_running()
  File "/usr/local/lib/python3.11/asyncio/base_events.py", line 589, in _check_running
    raise RuntimeError('This event loop is already running')
RuntimeError: This event loop is already running

During handling of the above exception, another exception occurred:

Traceback (most recent call last):
  File "/usr/local/lib/python3.11/site-packages/telegram/ext/_application.py", line 1079, in __run
    loop.run_until_complete(self.shutdown())
  File "/usr/local/lib/python3.11/asyncio/base_events.py", line 630, in run_until_complete
    self._check_running()
  File "/usr/local/lib/python3.11/asyncio/base_events.py", line 589, in _check_running
    raise RuntimeError('This event loop is already running')
RuntimeError: This event loop is already running

During handling of the above exception, another exception occurred:

Traceback (most recent call last):
  File "/app/src/main.py", line 31, in run_bot
    await module.main()
          ^^^^^^^^^^^^^
  File "/app/src/admin_bot/main.py", line 50, in main
    application.run_polling()
  File "/usr/local/lib/python3.11/site-packages/telegram/ext/_application.py", line 839, in run_polling
    return self.__run(
           ^^^^^^^^^^^
  File "/usr/local/lib/python3.11/site-packages/telegram/ext/_application.py", line 1084, in __run
    loop.close()
  File "/usr/local/lib/python3.11/asyncio/unix_events.py", line 68, in close
    super().close()
  File "/usr/local/lib/python3.11/asyncio/selector_events.py", line 88, in close
    raise RuntimeError("Cannot close a running event loop")
RuntimeError: Cannot close a running event loop
2025-10-07 07:52:27,407 - __main__ - INFO - üöÄ –ó–∞–ø—É—Å–∫ Notification Bot...
2025-10-07 07:52:27,424 - __main__ - ERROR - ‚ùå –û—à–∏–±–∫–∞ –ø—Ä–∏ –∑–∞–ø—É—Å–∫–µ Notification Bot: name 'name' is not defined
Traceback (most recent call last):
  File "/app/src/main.py", line 30, in run_bot
    module = __import__(f"src.{bot_module}", fromlist=['main'])
             ^^^^^^^^^^^^^^^^^^^^^^^^^^^^^^^^^^^^^^^^^^^^^^^^^^
  File "/app/src/notification_bot.py", line 20, in <module>
    logger = logging.getLogger(name)
                               ^^^^
NameError: name 'name' is not defined
2025-10-07 07:52:27,434 - __main__ - INFO - üöÄ –ó–∞–ø—É—Å–∫ Audit Bot...
2025-10-07 07:52:27,482 - __main__ - ERROR - ‚ùå –û—à–∏–±–∫–∞ –ø—Ä–∏ –∑–∞–ø—É—Å–∫–µ Audit Bot: Cannot close a running event loop
Traceback (most recent call last):
  File "/usr/local/lib/python3.11/site-packages/telegram/ext/_application.py", line 1054, in __run
    loop.run_until_complete(self._bootstrap_initialize(max_retries=bootstrap_retries))
  File "/usr/local/lib/python3.11/asyncio/base_events.py", line 630, in run_until_complete
    self._check_running()
  File "/usr/local/lib/python3.11/asyncio/base_events.py", line 589, in _check_running
    raise RuntimeError('This event loop is already running')
RuntimeError: This event loop is already running

During handling of the above exception, another exception occurred:

Traceback (most recent call last):
  File "/usr/local/lib/python3.11/site-packages/telegram/ext/_application.py", line 1079, in __run
    loop.run_until_complete(self.shutdown())
  File "/usr/local/lib/python3.11/asyncio/base_events.py", line 630, in run_until_complete
    self._check_running()
  File "/usr/local/lib/python3.11/asyncio/base_events.py", line 589, in _check_running
    raise RuntimeError('This event loop is already running')
RuntimeError: This event loop is already running

During handling of the above exception, another exception occurred:

Traceback (most recent call last):
  File "/app/src/main.py", line 31, in run_bot
    await module.main()
          ^^^^^^^^^^^^^
  File "/app/src/audit_bot.py", line 26, in main
    application.run_polling()
  File "/usr/local/lib/python3.11/site-packages/telegram/ext/_application.py", line 839, in run_polling
    return self.__run(
           ^^^^^^^^^^^
  File "/usr/local/lib/python3.11/site-packages/telegram/ext/_application.py", line 1084, in __run
    loop.close()
  File "/usr/local/lib/python3.11/asyncio/unix_events.py", line 68, in close
    super().close()
  File "/usr/local/lib/python3.11/asyncio/selector_events.py", line 88, in close
    raise RuntimeError("Cannot close a running event loop")
RuntimeError: Cannot close a running event loop
